Workbook

Sheet Societies (Master)
A1: AIMS Member Societies – Master List
A2: ID | B2: Society (official AIMS name) | C2: Region | D2: Section | E2: Section as of | F2: Section history | G2: 23/24 | H2: 24/25 | I2: 25/26 | J2: 26/27 | K2: 27/28 | L2: Seasons active | M2: Name(s) used in season tabs | N2: Notes
A3: =ROW()-2 -> 1 | B3: 9 Arch Musical Society | C3: Western | D3: Gilbert | E3: 26/27 | F3: 23/24: Sullivan · 24/25: Gilbert · 25/26: Gilbert · 26/27: Gilbert · 27/28: Gilbert | G3: =IF(COUNTIF('AIMS Calendar 2324'!$C:$C,$B3)>0,"Y","-") -> Y | H3: =IF(COUNTIF('AIMS Season - 24_25'!$C:$C,$B3)>0,"Y","-") -> Y | I3: =IF(COUNTIF('AIMS Season 2526'!$C:$C,$B3)>0,"Y","-") -> Y | J3: =IF(COUNTIF('AIMS Season 2627'!$C:$C,$B3)>0,"Y","-") -> Y | K3: =IF(COUNTIF('AIMS Season 2728'!$C:$C,$B3)>0,"Y","-") -> Y | L3: =COUNTIF($G3:$K3,"Y") -> 5 | M3: 9 Arch Musical Society; 9Arch MS
A4: =ROW()-2 -> 2 | B4: Achill Musical & Dramatic Society | C4: Western | D4: Non-AIMS | G4: =IF(COUNTIF('AIMS Calendar 2324'!$C:$C,$B4)>0,"Y","-") -> - | H4: =IF(COUNTIF('AIMS Season - 24_25'!$C:$C,$B4)>0,"Y","-") -> Y | I4: =IF(COUNTIF('AIMS Season 2526'!$C:$C,$B4)>0,"Y","-") -> - | J4: =IF(COUNTIF('AIMS Season 2627'!$C:$C,$B4)>0,"Y","-") -> Y | K4: =IF(COUNTIF('AIMS Season 2728'!$C:$C,$B4)>0,"Y","-") -> Y | L4: =COUNTIF($G4:$K4,"Y") -> 3 | M4: Achill Musical & Dramatic Society | N4: Not on AIMS register
A5: =ROW()-2 -> 3 | B5: Aghada Centre Theatre Group | C5: South-West | D5: Gilbert | E5: 26/27 | F5: 23/24: Sullivan · 24/25: Sullivan · 25/26: Gilbert · 26/27: Gilbert · 27/28: Sullivan | G5: =IF(COUNTIF('AIMS Calendar 2324'!$C:$C,$B5)>0,"Y","-") -> Y | H5: =IF(COUNTIF('AIMS Season - 24_25'!$C:$C,$B5)>0,"Y","-") -> Y | I5: =IF(COUNTIF('AIMS Season 2526'!$C:$C,$B5)>0,"Y","-") -> Y | J5: =IF(COUNTIF('AIMS Season 2627'!$C:$C,$B5)>0,"Y","-") -> Y | K5: =IF(COUNTIF('AIMS Season 2728'!$C:$C,$B5)>0,"Y","-") -> Y | L5: =COUNTIF($G5:$K5,"Y") -> 5 | M5: Aghada Centre Theatre Group
A6: =ROW()-2 -> 4 | B6: Athlone Musical Society | C6: Midlands | D6: Gilbert | E6: 26/27 | G6: =IF(COUNTIF('AIMS Calendar 2324'!$C:$C,$B6)>0,"Y","-") -> Y | H6: =IF(COUNTIF('AIMS Season - 24_25'!$C:$C,$B6)>0,"Y","-") -> Y | I6: =IF(COUNTIF('AIMS Season 2526'!$C:$C,$B6)>0,"Y","-") -> Y | J6: =IF(COUNTIF('AIMS Season 2627'!$C:$C,$B6)>0,"Y","-") -> Y | K6: =IF(COUNTIF('AIMS Season 2728'!$C:$C,$B6)>0,"Y","-") -> Y | L6: =COUNTIF($G6:$K6,"Y") -> 5 | M6: Athlone MS
A7: =ROW()-2 -> 5 | B7: Avonmore Musical Society | C7: South-East | D7: Gilbert | E7: 26/27 | F7: 23/24: Gilbert · 24/25: Gilbert · 25/26: Sullivan · 26/27: Gilbert · 27/28: Gilbert | G7: =IF(COUNTIF('AIMS Calendar 2324'!$C:$C,$B7)>0,"Y","-") -> Y | H7: =IF(COUNTIF('AIMS Season - 24_25'!$C:$C,$B7)>0,"Y","-") -> Y | I7: =IF(COUNTIF('AIMS Season 2526'!$C:$C,$B7)>0,"Y","-") -> Y | J7: =IF(COUNTIF('AIMS Season 2627'!$C:$C,$B7)>0,"Y","-") -> Y | K7: =IF(COUNTIF('AIMS Season 2728'!$C:$C,$B7)>0,"Y","-") -> Y | L7: =COUNTIF($G7:$K7,"Y") -> 5 | M7: Avonmore MS
A8: =ROW()-2 -> 6 | B8: Baldoyle Musical Society | C8: Eastern | D8: Sullivan | E8: 26/27 | G8: =IF(COUNTIF('AIMS Calendar 2324'!$C:$C,$B8)>0,"Y","-") -> Y | H8: =IF(COUNTIF('AIMS Season - 24_25'!$C:$C,$B8)>0,"Y","-") -> Y | I8: =IF(COUNTIF('AIMS Season 2526'!$C:$C,$B8)>0,"Y","-") -> Y | J8: =IF(COUNTIF('AIMS Season 2627'!$C:$C,$B8)>0,"Y","-") -> Y | K8: =IF(COUNTIF('AIMS Season 2728'!$C:$C,$B8)>0,"Y","-") -> Y | L8: =COUNTIF($G8:$K8,"Y") -> 5 | M8: Baldoyle MS; Baldoyle Musical Society
A9: =ROW()-2 -> 7 | B9: Ballinasloe Musical Society | C9: Midlands | D9: Sullivan | E9: 26/27 | G9: =IF(COUNTIF('AIMS Calendar 2324'!$C:$C,$B9)>0,"Y","-") -> Y | H9: =IF(COUNTIF('AIMS Season - 24_25'!$C:$C,$B9)>0,"Y","-") -> Y | I9: =IF(COUNTIF('AIMS Season 2526'!$C:$C,$B9)>0,"Y","-") -> Y | J9: =IF(COUNTIF('AIMS Season 2627'!$C:$C,$B9)>0,"Y","-") -> Y | K9: =IF(COUNTIF('AIMS Season 2728'!$C:$C,$B9)>0,"Y","-") -> Y | L9: =COUNTIF($G9:$K9,"Y") -> 5 | M9: Ballinsaloe MS; Ballinsaloe Musical Society
A10: =ROW()-2 -> 8 | B10: Ballinrobe Musical Society | C10: Western | D10: Gilbert | E10: 26/27 | G10: =IF(COUNTIF('AIMS Calendar 2324'!$C:$C,$B10)>0,"Y","-") -> Y | H10: =IF(COUNTIF('AIMS Season - 24_25'!$C:$C,$B10)>0,"Y","-") -> Y | I10: =IF(COUNTIF('AIMS Season 2526'!$C:$C,$B10)>0,"Y","-") -> Y | J10: =IF(COUNTIF('AIMS Season 2627'!$C:$C,$B10)>0,"Y","-") -> Y | K10: =IF(COUNTIF('AIMS Season 2728'!$C:$C,$B10)>0,"Y","-") -> Y | L10: =COUNTIF($G10:$K10,"Y") -> 5 | M10: Ballinrobe MS; Ballinrobe Musical Society
A11: =ROW()-2 -> 9 | B11: Ballyshannon Musical Society | C11: Northern | D11: Sullivan | E11: 26/27 | G11: =IF(COUNTIF('AIMS Calendar 2324'!$C:$C,$B11)>0,"Y","-") -> Y | H11: =IF(COUNTIF('AIMS Season - 24_25'!$C:$C,$B11)>0,"Y","-") -> Y | I11: =IF(COUNTIF('AIMS Season 2526'!$C:$C,$B11)>0,"Y","-") -> Y | J11: =IF(COUNTIF('AIMS Season 2627'!$C:$C,$B11)>0,"Y","-") -> Y | K11: =IF(COUNTIF('AIMS Season 2728'!$C:$C,$B11)>0,"Y","-") -> Y | L11: =COUNTIF($G11:$K11,"Y") -> 5 | M11: Ballyshannon Musical Society
A12: =ROW()-2 -> 10 | B12: Ballywillan Drama Group | C12: Northern | D12: Sullivan | E12: 26/27 | F12: 23/24: Gilbert · 24/25: Sullivan · 25/26: Sullivan · 26/27: Sullivan · 27/28: Sullivan | G12: =IF(COUNTIF('AIMS Calendar 2324'!$C:$C,$B12)>0,"Y","-") -> Y | H12: =IF(COUNTIF('AIMS Season - 24_25'!$C:$C,$B12)>0,"Y","-") -> Y | I12: =IF(COUNTIF('AIMS Season 2526'!$C:$C,$B12)>0,"Y","-") -> Y | J12: =IF(COUNTIF('AIMS Season 2627'!$C:$C,$B12)>0,"Y","-") -> Y | K12: =IF(COUNTIF('AIMS Season 2728'!$C:$C,$B12)>0,"Y","-") -> Y | L12: =COUNTIF($G12:$K12,"Y") -> 5 | M12: Ballywillan Drama Group
A13: =ROW()-2 -> 11 | B13: Banbridge Musical Society | C13: Northern | D13: Gilbert | E13: 24/25 | G13: =IF(COUNTIF('AIMS Calendar 2324'!$C:$C,$B13)>0,"Y","-") -> Y | H13: =IF(COUNTIF('AIMS Season - 24_25'!$C:$C,$B13)>0,"Y","-") -> Y | I13: =IF(COUNTIF('AIMS Season 2526'!$C:$C,$B13)>0,"Y","-") -> - | J13: =IF(COUNTIF('AIMS Season 2627'!$C:$C,$B13)>0,"Y","-") -> - | K13: =IF(COUNTIF('AIMS Season 2728'!$C:$C,$B13)>0,"Y","-") -> Y | L13: =COUNTIF($G13:$K13,"Y") -> 3 | M13: Banbridge Musical Society
A14: =ROW()-2 -> 12 | B14: Belfast Operatic Company | C14: Northern | D14: Gilbert | E14: 26/27 | G14: =IF(COUNTIF('AIMS Calendar 2324'!$C:$C,$B14)>0,"Y","-") -> Y | H14: =IF(COUNTIF('AIMS Season - 24_25'!$C:$C,$B14)>0,"Y","-") -> Y | I14: =IF(COUNTIF('AIMS Season 2526'!$C:$C,$B14)>0,"Y","-") -> Y | J14: =IF(COUNTIF('AIMS Season 2627'!$C:$C,$B14)>0,"Y","-") -> Y | K14: =IF(COUNTIF('AIMS Season 2728'!$C:$C,$B14)>0,"Y","-") -> Y | L14: =COUNTIF($G14:$K14,"Y") -> 5 | M14: Belfast Operatic; Belfast Operatic Company
A15: =ROW()-2 -> 13 | B15: Bellvue Academy of Performing Arts | C15: South-West | D15: Sullivan | E15: 26/27 | G15: =IF(COUNTIF('AIMS Calendar 2324'!$C:$C,$B15)>0,"Y","-") -> Y | H15: =IF(COUNTIF('AIMS Season - 24_25'!$C:$C,$B15)>0,"Y","-") -> Y | I15: =IF(COUNTIF('AIMS Season 2526'!$C:$C,$B15)>0,"Y","-") -> Y | J15: =IF(COUNTIF('AIMS Season 2627'!$C:$C,$B15)>0,"Y","-") -> Y | K15: =IF(COUNTIF('AIMS Season 2728'!$C:$C,$B15)>0,"Y","-") -> Y | L15: =COUNTIF($G15:$K15,"Y") -> 5 | M15: Bellvue Academy; Bellvue Academy of Performing Arts; Bellvue Youth Academy
A16: =ROW()-2 -> 14 | B16: Birr Stage Guild | C16: Midlands | D16: Sullivan | E16: 26/27 | G16: =IF(COUNTIF('AIMS Calendar 2324'!$C:$C,$B16)>0,"Y","-") -> Y | H16: =IF(COUNTIF('AIMS Season - 24_25'!$C:$C,$B16)>0,"Y","-") -> Y | I16: =IF(COUNTIF('AIMS Season 2526'!$C:$C,$B16)>0,"Y","-") -> Y | J16: =IF(COUNTIF('AIMS Season 2627'!$C:$C,$B16)>0,"Y","-") -> Y | K16: =IF(COUNTIF('AIMS Season 2728'!$C:$C,$B16)>0,"Y","-") -> Y | L16: =COUNTIF($G16:$K16,"Y") -> 5 | M16: Birr Stage Guild
A17: =ROW()-2 -> 15 | B17: Bosco Drama Group | C17: Northern | D17: Gilbert | E17: 26/27 | F17: 23/24: Sullivan · 24/25: Gilbert · 25/26: Gilbert · 26/27: Gilbert · 27/28: Gilbert | G17: =IF(COUNTIF('AIMS Calendar 2324'!$C:$C,$B17)>0,"Y","-") -> Y | H17: =IF(COUNTIF('AIMS Season - 24_25'!$C:$C,$B17)>0,"Y","-") -> Y | I17: =IF(COUNTIF('AIMS Season 2526'!$C:$C,$B17)>0,"Y","-") -> Y | J17: =IF(COUNTIF('AIMS Season 2627'!$C:$C,$B17)>0,"Y","-") -> Y | K17: =IF(COUNTIF('AIMS Season 2728'!$C:$C,$B17)>0,"Y","-") -> Y | L17: =COUNTIF($G17:$K17,"Y") -> 5 | M17: BOSCO (Newry)
A18: =ROW()-2 -> 16 | B18: Boyle Musical Society | C18: Western | D18: Sullivan | E18: 26/27 | G18: =IF(COUNTIF('AIMS Calendar 2324'!$C:$C,$B18)>0,"Y","-") -> Y | H18: =IF(COUNTIF('AIMS Season - 24_25'!$C:$C,$B18)>0,"Y","-") -> Y | I18: =IF(COUNTIF('AIMS Season 2526'!$C:$C,$B18)>0,"Y","-") -> Y | J18: =IF(COUNTIF('AIMS Season 2627'!$C:$C,$B18)>0,"Y","-") -> Y | K18: =IF(COUNTIF('AIMS Season 2728'!$C:$C,$B18)>0,"Y","-") -> Y | L18: =COUNTIF($G18:$K18,"Y") -> 5 | M18: Boyle MS; Boyle Musical Society
A19: =ROW()-2 -> 17 | B19: Bravo Theatre Group | C19: Western | D19: Gilbert | E19: 26/27 | G19: =IF(COUNTIF('AIMS Calendar 2324'!$C:$C,$B19)>0,"Y","-") -> Y | H19: =IF(COUNTIF('AIMS Season - 24_25'!$C:$C,$B19)>0,"Y","-") -> Y | I19: =IF(COUNTIF('AIMS Season 2526'!$C:$C,$B19)>0,"Y","-") -> Y | J19: =IF(COUNTIF('AIMS Season 2627'!$C:$C,$B19)>0,"Y","-") -> Y | K19: =IF(COUNTIF('AIMS Season 2728'!$C:$C,$B19)>0,"Y","-") -> Y | L19: =COUNTIF($G19:$K19,"Y") -> 5 | M19: Bravo; Bravo Theatre Group
A20: =ROW()-2 -> 18 | B20: Bray Musical Society | C20: South-East | D20: Sullivan | E20: 26/27 | G20: =IF(COUNTIF('AIMS Calendar 2324'!$C:$C,$B20)>0,"Y","-") -> Y | H20: =IF(COUNTIF('AIMS Season - 24_25'!$C:$C,$B20)>0,"Y","-") -> Y | I20: =IF(COUNTIF('AIMS Season 2526'!$C:$C,$B20)>0,"Y","-") -> Y | J20: =IF(COUNTIF('AIMS Season 2627'!$C:$C,$B20)>0,"Y","-") -> Y | K20: =IF(COUNTIF('AIMS Season 2728'!$C:$C,$B20)>0,"Y","-") -> Y | L20: =COUNTIF($G20:$K20,"Y") -> 5 | M20: Bray MS; Bray Musical Society
A21: =ROW()-2 -> 19 | B21: Carnew Musical Society | C21: South-East | D21: Gilbert | E21: 26/27 | G21: =IF(COUNTIF('AIMS Calendar 2324'!$C:$C,$B21)>0,"Y","-") -> Y | H21: =IF(COUNTIF('AIMS Season - 24_25'!$C:$C,$B21)>0,"Y","-") -> Y | I21: =IF(COUNTIF('AIMS Season 2526'!$C:$C,$B21)>0,"Y","-") -> Y | J21: =IF(COUNTIF('AIMS Season 2627'!$C:$C,$B21)>0,"Y","-") -> Y | K21: =IF(COUNTIF('AIMS Season 2728'!$C:$C,$B21)>0,"Y","-") -> Y | L21: =COUNTIF($G21:$K21,"Y") -> 5 | M21: Carnew MS
A22: =ROW()-2 -> 20 | B22: Carrick-on-Suir Musical Society | C22: South-West | D22: Gilbert | E22: 26/27 | G22: =IF(COUNTIF('AIMS Calendar 2324'!$C:$C,$B22)>0,"Y","-") -> Y | H22: =IF(COUNTIF('AIMS Season - 24_25'!$C:$C,$B22)>0,"Y","-") -> Y | I22: =IF(COUNTIF('AIMS Season 2526'!$C:$C,$B22)>0,"Y","-") -> Y | J22: =IF(COUNTIF('AIMS Season 2627'!$C:$C,$B22)>0,"Y","-") -> Y | K22: =IF(COUNTIF('AIMS Season 2728'!$C:$C,$B22)>0,"Y","-") -> Y | L22: =COUNTIF($G22:$K22,"Y") -> 5 | M22: Carrick-on-Suir; Carrick-on-Suir Musical Society
A23: =ROW()-2 -> 21 | B23: Carrigaline Musical Society | C23: South-West | D23: Sullivan | E23: 26/27 | G23: =IF(COUNTIF('AIMS Calendar 2324'!$C:$C,$B23)>0,"Y","-") -> - | H23: =IF(COUNTIF('AIMS Season - 24_25'!$C:$C,$B23)>0,"Y","-") -> Y | I23: =IF(COUNTIF('AIMS Season 2526'!$C:$C,$B23)>0,"Y","-") -> - | J23: =IF(COUNTIF('AIMS Season 2627'!$C:$C,$B23)>0,"Y","-") -> Y | K23: =IF(COUNTIF('AIMS Season 2728'!$C:$C,$B23)>0,"Y","-") -> Y | L23: =COUNTIF($G23:$K23,"Y") -> 3 | M23: Carrigaline Musical Society
A24: =ROW()-2 -> 22 | B24: Castlebar Musical & Dramatic Society | C24: Western | D24: Sullivan | E24: 26/27 | G24: =IF(COUNTIF('AIMS Calendar 2324'!$C:$C,$B24)>0,"Y","-") -> Y | H24: =IF(COUNTIF('AIMS Season - 24_25'!$C:$C,$B24)>0,"Y","-") -> Y | I24: =IF(COUNTIF('AIMS Season 2526'!$C:$C,$B24)>0,"Y","-") -> Y | J24: =IF(COUNTIF('AIMS Season 2627'!$C:$C,$B24)>0,"Y","-") -> Y | K24: =IF(COUNTIF('AIMS Season 2728'!$C:$C,$B24)>0,"Y","-") -> Y | L24: =COUNTIF($G24:$K24,"Y") -> 5 | M24: Castlebar Musical & Dramatic Society
A25: =ROW()-2 -> 23 | B25: Castlerea Musical Society | C25: Western | D25: Sullivan | E25: 26/27 | G25: =IF(COUNTIF('AIMS Calendar 2324'!$C:$C,$B25)>0,"Y","-") -> Y | H25: =IF(COUNTIF('AIMS Season - 24_25'!$C:$C,$B25)>0,"Y","-") -> Y | I25: =IF(COUNTIF('AIMS Season 2526'!$C:$C,$B25)>0,"Y","-") -> Y | J25: =IF(COUNTIF('AIMS Season 2627'!$C:$C,$B25)>0,"Y","-") -> Y | K25: =IF(COUNTIF('AIMS Season 2728'!$C:$C,$B25)>0,"Y","-") -> Y | L25: =COUNTIF($G25:$K25,"Y") -> 5 | M25: Castlerea; Castlerea Musical Society
A26: =ROW()-2 -> 24 | B26: Cecilian Musical Society, Limerick | C26: South-West | D26: Gilbert | E26: 26/27 | G26: =IF(COUNTIF('AIMS Calendar 2324'!$C:$C,$B26)>0,"Y","-") -> Y | H26: =IF(COUNTIF('AIMS Season - 24_25'!$C:$C,$B26)>0,"Y","-") -> Y | I26: =IF(COUNTIF('AIMS Season 2526'!$C:$C,$B26)>0,"Y","-") -> Y | J26: =IF(COUNTIF('AIMS Season 2627'!$C:$C,$B26)>0,"Y","-") -> Y | K26: =IF(COUNTIF('AIMS Season 2728'!$C:$C,$B26)>0,"Y","-") -> Y | L26: =COUNTIF($G26:$K26,"Y") -> 5 | M26: Cecilian MS Limerick
A27: =ROW()-2 -> 25 | B27: Clane Musical & Dramatic Society | C27: Eastern | D27: Sullivan | E27: 26/27 | F27: 23/24: Sullivan · 24/25: Sullivan · 25/26: Gilbert · 26/27: Sullivan · 27/28: Sullivan | G27: =IF(COUNTIF('AIMS Calendar 2324'!$C:$C,$B27)>0,"Y","-") -> Y | H27: =IF(COUNTIF('AIMS Season - 24_25'!$C:$C,$B27)>0,"Y","-") -> Y | I27: =IF(COUNTIF('AIMS Season 2526'!$C:$C,$B27)>0,"Y","-") -> Y | J27: =IF(COUNTIF('AIMS Season 2627'!$C:$C,$B27)>0,"Y","-") -> Y | K27: =IF(COUNTIF('AIMS Season 2728'!$C:$C,$B27)>0,"Y","-") -> Y | L27: =COUNTIF($G27:$K27,"Y") -> 5 | M27: Clane MS; Clane Musical Society
A28: =ROW()-2 -> 26 | B28: Clara Musical Society | C28: Midlands | D28: Gilbert | E28: 26/27 | G28: =IF(COUNTIF('AIMS Calendar 2324'!$C:$C,$B28)>0,"Y","-") -> Y | H28: =IF(COUNTIF('AIMS Season - 24_25'!$C:$C,$B28)>0,"Y","-") -> Y | I28: =IF(COUNTIF('AIMS Season 2526'!$C:$C,$B28)>0,"Y","-") -> Y | J28: =IF(COUNTIF('AIMS Season 2627'!$C:$C,$B28)>0,"Y","-") -> Y | K28: =IF(COUNTIF('AIMS Season 2728'!$C:$C,$B28)>0,"Y","-") -> Y | L28: =COUNTIF($G28:$K28,"Y") -> 5 | M28: Clara Musical Society
A29: =ROW()-2 -> 27 | B29: Claremorris Musical Society | C29: Western | D29: Sullivan | E29: 26/27 | G29: =IF(COUNTIF('AIMS Calendar 2324'!$C:$C,$B29)>0,"Y","-") -> Y | H29: =IF(COUNTIF('AIMS Season - 24_25'!$C:$C,$B29)>0,"Y","-") -> Y | I29: =IF(COUNTIF('AIMS Season 2526'!$C:$C,$B29)>0,"Y","-") -> Y | J29: =IF(COUNTIF('AIMS Season 2627'!$C:$C,$B29)>0,"Y","-") -> Y | K29: =IF(COUNTIF('AIMS Season 2728'!$C:$C,$B29)>0,"Y","-") -> Y | L29: =COUNTIF($G29:$K29,"Y") -> 5 | M29: Claremorris MS; Claremorris Musical Society
A30: =ROW()-2 -> 28 | B30: Coolmine Musical Society | C30: Eastern | D30: Gilbert | E30: 26/27 | G30: =IF(COUNTIF('AIMS Calendar 2324'!$C:$C,$B30)>0,"Y","-") -> Y | H30: =IF(COUNTIF('AIMS Season - 24_25'!$C:$C,$B30)>0,"Y","-") -> Y | I30: =IF(COUNTIF('AIMS Season 2526'!$C:$C,$B30)>0,"Y","-") -> Y | J30: =IF(COUNTIF('AIMS Season 2627'!$C:$C,$B30)>0,"Y","-") -> Y | K30: =IF(COUNTIF('AIMS Season 2728'!$C:$C,$B30)>0,"Y","-") -> Y | L30: =COUNTIF($G30:$K30,"Y") -> 5 | M30: Coolmine MS
A31: =ROW()-2 -> 29 | B31: Craic Theatre | C31: Northern | D31: Sullivan | E31: 23/24 | G31: =IF(COUNTIF('AIMS Calendar 2324'!$C:$C,$B31)>0,"Y","-") -> Y | H31: =IF(COUNTIF('AIMS Season - 24_25'!$C:$C,$B31)>0,"Y","-") -> - | I31: =IF(COUNTIF('AIMS Season 2526'!$C:$C,$B31)>0,"Y","-") -> - | J31: =IF(COUNTIF('AIMS Season 2627'!$C:$C,$B31)>0,"Y","-") -> - | K31: =IF(COUNTIF('AIMS Season 2728'!$C:$C,$B31)>0,"Y","-") -> - | L31: =COUNTIF($G31:$K31,"Y") -> 1 | M31: CRAIC
A32: =ROW()-2 -> 30 | B32: Creative Minds Productions | C32: South-West | D32: Sullivan | E32: 26/27 | G32: =IF(COUNTIF('AIMS Calendar 2324'!$C:$C,$B32)>0,"Y","-") -> - | H32: =IF(COUNTIF('AIMS Season - 24_25'!$C:$C,$B32)>0,"Y","-") -> - | I32: =IF(COUNTIF('AIMS Season 2526'!$C:$C,$B32)>0,"Y","-") -> Y | J32: =IF(COUNTIF('AIMS Season 2627'!$C:$C,$B32)>0,"Y","-") -> Y | K32: =IF(COUNTIF('AIMS Season 2728'!$C:$C,$B32)>0,"Y","-") -> Y | L32: =COUNTIF($G32:$K32,"Y") -> 3 | M32: Creative Minds Productions
A33: =ROW()-2 -> 31 | B33: DCG Project, The | C33: Eastern | D33: Sullivan | E33: 26/27 | G33: =IF(COUNTIF('AIMS Calendar 2324'!$C:$C,$B33)>0,"Y","-") -> - | H33: =IF(COUNTIF('AIMS Season - 24_25'!$C:$C,$B33)>0,"Y","-") -> - | I33: =IF(COUNTIF('AIMS Season 2526'!$C:$C,$B33)>0,"Y","-") -> - | J33: =IF(COUNTIF('AIMS Season 2627'!$C:$C,$B33)>0,"Y","-") -> Y | K33: =IF(COUNTIF('AIMS Season 2728'!$C:$C,$B33)>0,"Y","-") -> Y | L33: =COUNTIF($G33:$K33,"Y") -> 2 | M33: The DCG Project
A34: =ROW()-2 -> 32 | B34: DCU Drama Society | C34: Eastern | D34: Sullivan | E34: 23/24 | G34: =IF(COUNTIF('AIMS Calendar 2324'!$C:$C,$B34)>0,"Y","-") -> Y | H34: =IF(COUNTIF('AIMS Season - 24_25'!$C:$C,$B34)>0,"Y","-") -> - | I34: =IF(COUNTIF('AIMS Season 2526'!$C:$C,$B34)>0,"Y","-") -> - | J34: =IF(COUNTIF('AIMS Season 2627'!$C:$C,$B34)>0,"Y","-") -> - | K34: =IF(COUNTIF('AIMS Season 2728'!$C:$C,$B34)>0,"Y","-") -> - | L34: =COUNTIF($G34:$K34,"Y") -> 1 | M34: DCU drama
A35: =ROW()-2 -> 33 | B35: Drogheda Musical Society | C35: Eastern | D35: Sullivan | E35: 26/27 | G35: =IF(COUNTIF('AIMS Calendar 2324'!$C:$C,$B35)>0,"Y","-") -> - | H35: =IF(COUNTIF('AIMS Season - 24_25'!$C:$C,$B35)>0,"Y","-") -> - | I35: =IF(COUNTIF('AIMS Season 2526'!$C:$C,$B35)>0,"Y","-") -> Y | J35: =IF(COUNTIF('AIMS Season 2627'!$C:$C,$B35)>0,"Y","-") -> Y | K35: =IF(COUNTIF('AIMS Season 2728'!$C:$C,$B35)>0,"Y","-") -> - | L35: =COUNTIF($G35:$K35,"Y") -> 2 | M35: Drogheda Musical Society
A36: =ROW()-2 -> 34 | B36: Dun Laoghaire Musical & Dramatic Society | C36: Eastern | D36: Gilbert | E36: 26/27 | F36: 23/24: Sullivan · 24/25: Sullivan · 25/26: Gilbert · 26/27: Gilbert · 27/28: Gilbert | G36: =IF(COUNTIF('AIMS Calendar 2324'!$C:$C,$B36)>0,"Y","-") -> Y | H36: =IF(COUNTIF('AIMS Season - 24_25'!$C:$C,$B36)>0,"Y","-") -> Y | I36: =IF(COUNTIF('AIMS Season 2526'!$C:$C,$B36)>0,"Y","-") -> Y | J36: =IF(COUNTIF('AIMS Season 2627'!$C:$C,$B36)>0,"Y","-") -> Y | K36: =IF(COUNTIF('AIMS Season 2728'!$C:$C,$B36)>0,"Y","-") -> Y | L36: =COUNTIF($G36:$K36,"Y") -> 5 | M36: DMDS; Dun Laoghaire MDS Musical Society
A37: =ROW()-2 -> 35 | B37: Dunboyne Musical Society | C37: Eastern | D37: Sullivan | E37: 26/27 | F37: 23/24: Gilbert · 24/25: Gilbert · 25/26: Sullivan · 26/27: Sullivan · 27/28: Gilbert | G37: =IF(COUNTIF('AIMS Calendar 2324'!$C:$C,$B37)>0,"Y","-") -> Y | H37: =IF(COUNTIF('AIMS Season - 24_25'!$C:$C,$B37)>0,"Y","-") -> Y | I37: =IF(COUNTIF('AIMS Season 2526'!$C:$C,$B37)>0,"Y","-") -> Y | J37: =IF(COUNTIF('AIMS Season 2627'!$C:$C,$B37)>0,"Y","-") -> Y | K37: =IF(COUNTIF('AIMS Season 2728'!$C:$C,$B37)>0,"Y","-") -> Y | L37: =COUNTIF($G37:$K37,"Y") -> 5 | M37: Dunboyne MS
A38: =ROW()-2 -> 36 | B38: Dundalk Musical Society | C38: Eastern | D38: Sullivan | E38: 26/27 | G38: =IF(COUNTIF('AIMS Calendar 2324'!$C:$C,$B38)>0,"Y","-") -> Y | H38: =IF(COUNTIF('AIMS Season - 24_25'!$C:$C,$B38)>0,"Y","-") -> Y | I38: =IF(COUNTIF('AIMS Season 2526'!$C:$C,$B38)>0,"Y","-") -> Y | J38: =IF(COUNTIF('AIMS Season 2627'!$C:$C,$B38)>0,"Y","-") -> Y | K38: =IF(COUNTIF('AIMS Season 2728'!$C:$C,$B38)>0,"Y","-") -> Y | L38: =COUNTIF($G38:$K38,"Y") -> 5 | M38: Dundalk Musical Society
A39: =ROW()-2 -> 37 | B39: Dunmore Musical Society | C39: Western | D39: Sullivan | E39: 24/25 | G39: =IF(COUNTIF('AIMS Calendar 2324'!$C:$C,$B39)>0,"Y","-") -> - | H39: =IF(COUNTIF('AIMS Season - 24_25'!$C:$C,$B39)>0,"Y","-") -> Y | I39: =IF(COUNTIF('AIMS Season 2526'!$C:$C,$B39)>0,"Y","-") -> - | J39: =IF(COUNTIF('AIMS Season 2627'!$C:$C,$B39)>0,"Y","-") -> - | K39: =IF(COUNTIF('AIMS Season 2728'!$C:$C,$B39)>0,"Y","-") -> - | L39: =COUNTIF($G39:$K39,"Y") -> 1 | M39: Dunmore Musical Society
A40: =ROW()-2 -> 38 | B40: East Clare Musical Society | C40: South-West | D40: Non-AIMS | G40: =IF(COUNTIF('AIMS Calendar 2324'!$C:$C,$B40)>0,"Y","-") -> - | H40: =IF(COUNTIF('AIMS Season - 24_25'!$C:$C,$B40)>0,"Y","-") -> - | I40: =IF(COUNTIF('AIMS Season 2526'!$C:$C,$B40)>0,"Y","-") -> Y | J40: =IF(COUNTIF('AIMS Season 2627'!$C:$C,$B40)>0,"Y","-") -> Y | K40: =IF(COUNTIF('AIMS Season 2728'!$C:$C,$B40)>0,"Y","-") -> Y | L40: =COUNTIF($G40:$K40,"Y") -> 3 | M40: East Clare Musical Society | N40: Not on AIMS register; region assigned geographically – please confirm
...

Sheet AIMS Season 2526
A1: Personal project - contact Darragh Carroll for amendments/updates @darraghcphotography
A2: Region | B2: Category (25/26) | C2: Society | D2: Show | E2: Opening | F2: Closing | G2: Adjudicator date | H2: Review Online | I2: Director | J2: Musical Director | K2: Choreographer
A3: Northern | B3: Sullivan | C3: Portrush Music Society | D3: My Fair Lady | E3: 45804 | F3: 45808 | G3: 45808 | H3: link | I3: Kerry Kane | J3: Terry Cloughley | K3: Rosemary O’Connor
A4: South-East | B4: Gilbert | C4: Jack Cunningham Productions | D4: All Shook Up | E4: 45903 | F4: 45906 | G4: 45906 | H4: link | I4: Jack Cunningham | J4: Andrew Lane | K4: Jack Cunningham
A5: Western | B5: Gilbert | C5: Bravo Theatre Group | D5: Come From Away | E5: 45910 | F5: 45912 | G5: 45911 | H5: link | I5: Aoife McClafferty | J5: Shane Farrell | K5: Aoife McClafferty
A6: Northern | B6: Gilbert | C6: St. Agnes Choral Society | D6: Come From Away | E6: 45904 | F6: 45913 | G6: 45913 | H6: link | I6: Rachel Logan-Fee | J6: Andrew Robinson | K6: Amy Blackshaw
A7: South-East | B7: Gilbert | C7: North Wexford Musical Theatre | D7: Into The Woods | E7: 45918 | F7: 45920 | G7: 45920 | H7: link | I7: Róisín Currid | J7: Conor McCarthy | K7: Róisín Currid
A8: Northern | B8: Gilbert | C8: Ulster Operatic Company | D8: 9 to 5 | E8: 45937 | F8: 45941 | G8: 45941 | H8: link | I8: Tony Finnegan | J8: Wilson Shields | K8: Matthew Watson
A9: Eastern | B9: Sullivan | C9: Dundalk Musical Society | D9: My Fair Lady | E9: 45945 | F9: 45949 | G9: 45946 | H9: link | I9: Tony Finnegan | J9: Elizabeth Freeburn | K9: Daniel Maguire
A10: Northern | B10: Sullivan | C10: Tullyvin Musical Society | D10: Made in Dagenham | E10: 45945 | F10: 45948 | G10: 45948 | H10: link | I10: Aoife Shalvey | J10: Dave McGauran | K10: Aisling Rountree
A11: Midlands | B11: Gilbert | C11: The Odd Theatre Company | D11: Jesus Christ Superstar | E11: 45953 | F11: 45955 | G11: 45955 | H11: link | I11: Cian O'Dowd | J11: Keelin Kilduff | K11: Áine Foley
A12: Eastern | B12: Gilbert | C12: Kilmainham Inchicore Musical Society | D12: Rodgers & Hammerstein's Cinderella | E12: 45959 | F12: 45962 | G12: 45959 | H12: link | I12: Sharon McNamara | J12: Amy Penston-Hendley | K12: Bernie O'Sullivan
A13: Northern | B13: Gilbert | C13: Bosco Drama Group | D13: Beauty and the Beast | E13: 45958 | F13: 45962 | G13: 45960 | H13: link | I13: Connie McCaughey | J13: Aislinn McGinn | K13: Ann Marie Morgan
A14: South-West | B14: Gilbert | C14: Muse Productions | D14: RENT | E14: 45959 | F14: 45962 | G14: 45962 | H14: link | I14: Martin McNelis | J14: Mary-Rose McNally | K14: Jay Molyneux
... A35: Western | B35: Gilbert | C35: Galway University Musical Society | D35: Follies | E35: 46056 | F35: 46060 | G35: 46060 | H35: link | I35: Keith Hanley | J35: Abbie Flannery | K35: Emily Smith
A36: South-West | B36: Gilbert | C36: Killarney Musical Society | D36: All Shook Up | E36: 46063 | F36: 46065 | G36: 46064 | H36: link | I36: Oliver Hurley | J36: Jimmy Brockie
A37: South-West | B37: Sullivan | C37: Shannon Musical Society | D37: Come From Away | E37: 46068 | F37: 46074 | G37: 46069 | H37: link | I37: Michael Anthony Greene | J37: Carmel Griffin | K37: Stephen O'Ríain
A38: South-West | B38: Gilbert | C38: Aghada Centre Theatre Group | D38: Legally Blonde | E38: 46068 | F38: 46074 | G38: 46070 | H38: link | I38: Sinead Dunlea | J38: Robbie Pender | K38: Chloe O'Leary
A39: Eastern | B39: Gilbert | C39: Malahide Musical & Dramatic Society | D39: The Witches of Eastwick | E39: 46070 | F39: 46074 | G39: 46071 | H39: link | I39: EJ Reilly | J39: Dave McGauran | K39: Karen McCourt
A40: South-West | B40: Gilbert | C40: Tipperary Musical Society | D40: Sweeney Todd | E40: 46070 | F40: 46074 | G40: 46072 | H40: link | I40: David Hennessy | J40: Mary-Rose McNally | K40: Amanda Kearns
A41: Midlands | B41: Gilbert | C41: Tullamore Musical Society | D41: We Will Rock You | E41: 46072 | F41: 46079 | G41: 46073 | H41: link | I41: Chris Coroon | J41: Enda O'Connor | K41: Laura Douglas
A42: Eastern | B42: Gilbert | C42: Entr'acte Musical Theatre Society | D42: Jesus Christ Superstar | E42: 46071 | F42: 46074 | G42: 46074 | H42: link | I42: Niamh McGowan | J42: Roisin Heenan | K42: Niamh McGowan
A43: Eastern | B43: Gilbert | C43: UCD Musical Society | D43: Carrie | E43: 46078 | F43: 46081 | G43: 46078 | H43: link | I43: Fionn O'Neill | J43: Cuan Egan | K43: Doireann McAuley
A44: South-West | B44: Sullivan | C44: Bellvue Academy of Performing Arts | D44: Hadestown: Teen Edition | E44: 46093 | F44: 46095 | G44: 46081 | H44: link | I44: Lisa Kelly | J44: Niall Kelly | K44: Keith Dwyer Greene
A45: Eastern | B45: Gilbert | C45: Trim Musical Society | D45: Legally Blonde | E45: 46083 | F45: 46088 | G45: 46085 | H45: link | I45: Emma Thornton | J45: Ben Cully | K45: Laura Douglas
A46: Midlands | B46: Gilbert | C46: Athlone Musical Society | D46: The Witches of Eastwick | E46: 46084 | F46: 46088 | G46: 46088 | H46: link | I46: Dominic Reid | J46: Ger Madden | K46: Kori Kilduff
A47: Eastern | B47: Sullivan | C47: Naas Musical Society | D47: We Will Rock You | E47: 46088 | F47: 46094 | G47: 46090 | H47: link | I47: Sharon McNamara | J47: Mairead McKenna | K47: Áine Foley
A48: Northern | B48: Sullivan | C48: Letterkenny Musical Society | D48: Come From Away | E48: 46091 | F48: 46095 | G48: 46092 | H48: link | I48: Maria Rushe | J48: Mark Bradley
A49: Northern | B49: Gilbert | C49: Londonderry Musical Society | D49: Kinky Boots | E49: 46092 | F49: 46095 | G49: 46092 | H49: link | I49: Alan McClarty | J49: Peter Doherty
A50: Eastern | B50: Sullivan | C50: Drogheda Musical Society | D50: The Addams Family | E50: 46093 | F50: 46095 | G50: 46093 | H50: link | I50: Sarah Louisa Nolan | J50: Megan Monerawela | K50: Aisling Nally
A51: South-West | B51: Sullivan | C51: Mary I Dramatic Arts Society | D51: Spongebob Squarepants | E51: 46093 | F51: 46095 | G51: 46094 | H51: link | I51: Bróna McGlinchey | J51: Michael Young | K51: Emily Flynn
A52: South-East | B52: Sullivan | C52: New Ross Musical Society | D52: Me and My Girl | E52: 46090 | F52: 46095 | G52: 46095 | H52: link | I52: Derek Shannon | J52: Jimmy Brockie | K52: Anne-Marie Cooney
A53: South-West | B53: Gilbert | C53: Mitchelstown Musical Society | D53: We Will Rock You | E53: 46099 | F53: 46102 | G53: 46101 | H53: link | I53: Lisa Kelly | J53: Eamon O'Malley | K53: `Henry James Fitzgerald
A54: South-West | B54: Sullivan | C54: Limerick Musical Society | D54: Michael Collins | E54: 46100 | F54: 46102 | G54: 46102 | H54: link | I54: Des Henn | J54: Michael Young | K54: Des Henn
A55: Eastern | B55: Gilbert | C55: Rush Musical Society | D55: The Drowsy Chaperone | E55: 46100 | F55: 46109 | G55: 46102 | H55: link | I55: Wilfie Pyper | J55: Sarah Lynch Barrett | K55: Eimear Sheridan
A56: Eastern | B56: Gilbert | C56: Teachers' Musical Society | D56: Jekyll & Hyde | E56: 46105 | F56: 46109 | G56: 46106 | H56: link | I56: EJ Reilly | J56: Dermot O'Callaghan | K56: Serena Salmon
A57: South-West | B57: Sullivan | C57: Nenagh Choral Society Ltd | D57: Evita | E57: 46105 | F57: 46109 | G57: 46107 | H57: link | I57: Greg Browne | J57: Laura Kearney | K57: Megan Maher
A58: South-West | B58: Gilbert | C58: Thurles Musical Society | D58: The Hunchback of Notre Dame | E58: 46105 | F58: 46109 | G58: 46108 | H58: link | I58: Michael Anthony Greene | J58: Mary-Rose McNally | K58: Michael Anthony Greene
A59: South-West | B59: Sullivan | C59: Youghal Musical Society | D59: Fiddler on the Roof | E59: 46105 | F59: 46108 | G59: 46108 | H59: link | I59: Seamus Power | J59: Anna O' Sullivan | K59: Kate O'Callaghan
A60: Western | B60: Sullivan | C60: Castlerea Musical Society | D60: Oklahoma Calendar Girls CANCELLED | E60: n/a | F60: n/a | G60: n/a | H60: n/a
...

Sheet AIMS Season 2627
A1: Region | B1: Category (TBC) | C1: Society | D1: Show | E1: Opening | F1: Closing | G1: Month | H1: Review Online | I1: Director | J1: Musical Director | K1: Choreographer
A2: South-West | B2: Sullivan | C2: Roscrea Musical Society | D2: Newsies | E2: 46138 | F2: 46143
A3: Northern | B3: Sullivan | C3: Belfast Operatic Company | D3: Guys and Dolls | E3: 46154 | F3: 46158
A4: Northern | B4: Sullivan | C4: Portrush Music Society | D4: Come From Away | E4: 46170 | F4: 46179
A5: Eastern | B5: Sullivan | C5: DCG Project, The | D5: RENT | E5: 46190 | F5: 46192 | I5: Dominic Reid | J5: Griffo | K5: Chris Corroon
A6: South-West | B6: Sullivan | C6: Creative Minds Productions | D6: Made in Dagenham | E6: 46204 | F6: 46207
A7: South-East | B7: Gilbert | C7: Jack Cunningham Productions | D7: West Side Story | E7: 46267 | F7: 46270 | I7: Jack Cunningham | J7: Andrew Lane | K7: Jack Cunningham
A8: South-East | B8: Sullivan | C8: North Wexford Musical Theatre | D8: Our House | E8: 46282 | F8: 46284 | I8: Roisin Currid | J8: Conor McCarthy
A9: Midlands | B9: Gilbert | C9: Clara Musical Society | D9: Dear Evan Hansen | E9: 46284 | F9: 46287
A10: Western | B10: Gilbert | C10: Bravo Theatre Group | D10: Dear Evan Hansen | E10: 46295 | F10: 46298
A11: South-East | B11: Sullivan | C11: St. Michael's Theatre Musical Society | D11: Michael Collins: A Musical Drama | E11: 46342 | F11: 46347
A12: Northern | B12: Gilbert | C12: Belfast Operatic Company | D12: Come From Away | E12: Feb
A13: Eastern | B13: Sullivan | C13: Drogheda Musical Society | D13: 9 to 5 | I13: Sarah Louisa Nolan | J13: Megan Monerawela | K13: Aisling Nally
A14: Western | B14: Gilbert | C14: 9 Arch Musical Society | D14: All Shook Up | J14: Kate Faherty
A15: South-West | B15: Gilbert | C15: Carrick-on-Suir Musical Society | D15: Beauty & The Beast
A16: Midlands | B16: Gilbert | C16: St. Mel's Musical Society, Longford | D16: Beauty & The Beast
A17: South-East | B17: Sullivan | C17: Bray Musical Society | D17: Beauty & The Beast
A18: Eastern | B18: Sullivan | C18: Dundalk Musical Society | D18: Calamity Jane
A19: Western | B19: Sullivan | C19: Claremorris Musical Society | D19: Calendar Girls
A20: Midlands | B20: Gilbert | C20: Newbridge Musical Society | D20: Chess
A21: South-West | B21: Gilbert | C21: St. Mary's Choral Society, Clonmel | D21: Chess
A22: South-West | B22: Gilbert | C22: Aghada Centre Theatre Group | D22: Come From Away
A23: Eastern | B23: Gilbert | C23: Dun Laoghaire Musical & Dramatic Society | D23: Come From Away
A24: South-West | B24: Gilbert | C24: Thurles Musical Society | D24: Come From Away
A25: Eastern | B25: Gilbert | C25: Rush Musical Society | D25: Come From Away
A26: South-East | B26: Gilbert | C26: Carnew Musical Society | D26: Evita
... A41: Midlands | B41: Gilbert | C41: The Odd Theatre Company | D41: My Fair Lady
A42: Eastern | B42: Gilbert | C42: Entr'acte Musical Theatre Society | D42: Newsies | I42: Gavin Murphy | J42: Ben Cully | K42: Leah Meagher
A43: South-West | B43: Sullivan | C43: Bellvue Academy of Performing Arts | D43: Newsies
A44: Eastern | B44: Gilbert | C44: UCD Musical Society | D44: Next To Normal
A45: South-West | B45: Gilbert | C45: Nenagh Choral Society Youth Academy | D45: NO SHOW THIS SEASON
A46: Western | B46: Sullivan | C46: Boyle Musical Society | D46: NO SHOW THIS SEASON
A47: Eastern | B47: Sullivan | C47: Kilmacud Musical Society | D47: Penzane! The Pirates Musical (New)
A48: Eastern | B48: Sullivan | C48: Baldoyle Musical Society | D48: Shrek
A49: Northern | B49: Gilbert | C49: St. Agnes Choral Society | D49: Shrek
A50: Northern | B50: Sullivan | C50: Tullyvin Musical Society | D50: Shrek
A51: Eastern | B51: Sullivan | C51: Dunboyne Musical Society | D51: Sister Act | I51: Orla Mulreid Deane | J51: Caitriona Ni Threasaigh | K51: Leah Meagher
A52: South-West | B52: Gilbert | C52: Killarney Musical Society | D52: Sister Act
A53: South-West | B53: Gilbert | C53: Tipperary Musical Society | D53: Sister Act
A54: Eastern | B54: Sullivan | C54: Clane Musical & Dramatic Society | D54: Sweeney Todd
...

Sheet Gilbert
A2: =IFERROR(__xludf.UNSUPPORTED("QUERY({'AIMS Calendar 2324'!A:BK}, ""SELECT * WHERE Col2 = 'Gilbert'"") "),"This is a personal project by Darragh Carroll / not an official AIMS piece! - if there are any gaps - feel free to get in touch with me at info@darraghc.ie - Or if you'd like to become an editor! Region") -> This is a personal project by Darragh Carroll / not an official AIMS piece! - if there are any gaps - feel free to get in touch with me at info@darraghc.ie - Or if you'd like to become an editor! Region | B2: =IFERROR(__xludf.UNSUPPORTED("""COMPUTED_VALUE""")," Category") -> Category | C2: =IFERROR(__xludf.UNSUPPORTED("""COMPUTED_VALUE""")," Society") -> Society | D2: =IFERROR(__xludf.UNSUPPORTED("""COMPUTED_VALUE""")," Show") -> Show | E2: =IFERROR(__xludf.UNSUPPORTED("""COMPUTED_VALUE""")," Opening") -> Opening | F2: =IFERROR(__xludf.UNSUPPORTED("""COMPUTED_VALUE""")," Closing") -> Closing | G2: =IFERROR(__xludf.UNSUPPORTED("""COMPUTED_VALUE""")," Review Online") -> Review Online | H2: =IFERROR(__xludf.UNSUPPORTED("""COMPUTED_VALUE""")," Director") -> Director | I2: =IFERROR(__xludf.UNSUPPORTED("""COMPUTED_VALUE""")," Choreographer") -> Choreographer | J2: =IFERROR(__xludf.UNSUPPORTED("""COMPUTED_VALUE""")," Musical Director") -> Musical Director | K2: =IFERROR(__xludf.UNSUPPORTED("""COMPUTED_VALUE""")," ") | L2: =IFERROR(__xludf.UNSUPPORTED("""COMPUTED_VALUE""")," ") | M2: =IFERROR(__xludf.UNSUPPORTED("""COMPUTED_VALUE""")," ") | N2: =IFERROR(__xludf.UNSUPPORTED("""COMPUTED_VALUE""")," ") | O2: =IFERROR(__xludf.UNSUPPORTED("""COMPUTED_VALUE""")," ") | P2: =IFERROR(__xludf.UNSUPPORTED("""COMPUTED_VALUE""")," ") | Q2: =IFERROR(__xludf.UNSUPPORTED("""COMPUTED_VALUE""")," ") | R2: =IFERROR(__xludf.UNSUPPORTED("""COMPUTED_VALUE""")," ") | ... AB2: =IFERROR(__xludf.UNSUPPORTED("""COMPUTED_VALUE""")," ")
A3: =IFERROR(__xludf.UNSUPPORTED("""COMPUTED_VALUE"""),"Northern") -> Northern | B3: =IFERROR(__xludf.UNSUPPORTED("""COMPUTED_VALUE"""),"Gilbert") -> Gilbert | C3: =IFERROR(__xludf.UNSUPPORTED("""COMPUTED_VALUE"""),"Ballywillan Drama Group") -> Ballywillan Drama Group | D3: =IFERROR(__xludf.UNSUPPORTED("""COMPUTED_VALUE"""),"Kinky Boots") -> Kinky Boots | E3: =IFERROR(__xludf.UNSUPPORTED("""COMPUTED_VALUE"""),45072) -> 45072 | F3: =IFERROR(__xludf.UNSUPPORTED("""COMPUTED_VALUE"""),45087) -> 45087 | G3: =IFERROR(__xludf.UNSUPPORTED("""COMPUTED_VALUE"""),"direct link") -> direct link | H3: =IFERROR(__xludf.UNSUPPORTED("""COMPUTED_VALUE"""),"Brian Logan") -> Brian Logan | I3: =IFERROR(__xludf.UNSUPPORTED("""COMPUTED_VALUE"""),"Laura Fisher") -> Laura Fisher | J3: =IFERROR(__xludf.UNSUPPORTED("""COMPUTED_VALUE"""),"Andrew Robinson") -> Andrew Robinson
A4: =IFERROR(__xludf.UNSUPPORTED("""COMPUTED_VALUE"""),"Northern") -> Northern | B4: =IFERROR(__xludf.UNSUPPORTED("""COMPUTED_VALUE"""),"Gilbert") -> Gilbert | C4: =IFERROR(__xludf.UNSUPPORTED("""COMPUTED_VALUE"""),"Ulster Operatic") -> Ulster Operatic | D4: =IFERROR(__xludf.UNSUPPORTED("""COMPUTED_VALUE"""),"Evita") -> Evita | E4: =IFERROR(__xludf.UNSUPPORTED("""COMPUTED_VALUE"""),45189) -> 45189 | F4: =IFERROR(__xludf.UNSUPPORTED("""COMPUTED_VALUE"""),45192) -> 45192 | G4: =IFERROR(__xludf.UNSUPPORTED("""COMPUTED_VALUE"""),"direct link") -> direct link | H4: =IFERROR(__xludf.UNSUPPORTED("""COMPUTED_VALUE"""),"Tony Finnegan") -> Tony Finnegan | I4: =IFERROR(__xludf.UNSUPPORTED("""COMPUTED_VALUE"""),"Ann Marie Morgan") -> Ann Marie Morgan | J4: =IFERROR(__xludf.UNSUPPORTED("""COMPUTED_VALUE"""),"Wilson Shields") -> Wilson Shields
A5: =IFERROR(__xludf.UNSUPPORTED("""COMPUTED_VALUE"""),"Eastern") -> Eastern | B5: =IFERROR(__xludf.UNSUPPORTED("""COMPUTED_VALUE"""),"Gilbert") -> Gilbert | C5: =IFERROR(__xludf.UNSUPPORTED("""COMPUTED_VALUE"""),"UCD") -> UCD | D5: =IFERROR(__xludf.UNSUPPORTED("""COMPUTED_VALUE"""),"Bare") -> Bare | E5: =IFERROR(__xludf.UNSUPPORTED("""COMPUTED_VALUE"""),45196) -> 45196 | F5: =IFERROR(__xludf.UNSUPPORTED("""COMPUTED_VALUE"""),45198) -> 45198 | G5: =IFERROR(__xludf.UNSUPPORTED("""COMPUTED_VALUE"""),"direct link") -> direct link | H5: =IFERROR(__xludf.UNSUPPORTED("""COMPUTED_VALUE"""),"Sorcha McGlynn") -> Sorcha McGlynn | I5: =IFERROR(__xludf.UNSUPPORTED("""COMPUTED_VALUE"""),"Brianna Kelly") -> Brianna Kelly | J5: =IFERROR(__xludf.UNSUPPORTED("""COMPUTED_VALUE"""),"Luke Shiels") -> Luke Shiels
A6: =IFERROR(__xludf.UNSUPPORTED("""COMPUTED_VALUE"""),"Western") -> Western | B6: =IFERROR(__xludf.UNSUPPORTED("""COMPUTED_VALUE"""),"Gilbert") -> Gilbert | C6: =IFERROR(__xludf.UNSUPPORTED("""COMPUTED_VALUE"""),"Bravo") -> Bravo | D6: =IFERROR(__xludf.UNSUPPORTED("""COMPUTED_VALUE"""),"Calendar Girls") -> Calendar Girls | E6: =IFERROR(__xludf.UNSUPPORTED("""COMPUTED_VALUE"""),45197) -> 45197 | F6: =IFERROR(__xludf.UNSUPPORTED("""COMPUTED_VALUE"""),45199) -> 45199 | G6: =IFERROR(__xludf.UNSUPPORTED("""COMPUTED_VALUE"""),"direct link") -> direct link | H6: =IFERROR(__xludf.UNSUPPORTED("""COMPUTED_VALUE"""),"Pat McElwain") -> Pat McElwain | I6: =IFERROR(__xludf.UNSUPPORTED("""COMPUTED_VALUE"""),"Jay Molyneux") -> Jay Molyneux | J6: =IFERROR(__xludf.UNSUPPORTED("""COMPUTED_VALUE"""),"Shane Farrell") -> Shane Farrell
A7: =IFERROR(__xludf.UNSUPPORTED("""COMPUTED_VALUE"""),"Western") -> Western | B7: =IFERROR(__xludf.UNSUPPORTED("""COMPUTED_VALUE"""),"Gilbert") -> Gilbert | C7: =IFERROR(__xludf.UNSUPPORTED("""COMPUTED_VALUE"""),"MCS") -> MCS | D7: =IFERROR(__xludf.UNSUPPORTED("""COMPUTED_VALUE"""),"Evita") -> Evita | E7: =IFERROR(__xludf.UNSUPPORTED("""COMPUTED_VALUE"""),45230) -> 45230 | F7: =IFERROR(__xludf.UNSUPPORTED("""COMPUTED_VALUE"""),45234) -> 45234 | G7: =IFERROR(__xludf.UNSUPPORTED("""COMPUTED_VALUE"""),"direct link") -> direct link | H7: =IFERROR(__xludf.UNSUPPORTED("""COMPUTED_VALUE"""),"Ronan Lardner") -> Ronan Lardner | I7: =IFERROR(__xludf.UNSUPPORTED("""COMPUTED_VALUE"""),"Jay Molyneux") -> Jay Molyneux | J7: =IFERROR(__xludf.UNSUPPORTED("""COMPUTED_VALUE"""),"Shane Farrell") -> Shane Farrell
A8: =IFERROR(__xludf.UNSUPPORTED("""COMPUTED_VALUE"""),"Eastern") -> Eastern | B8: =IFERROR(__xludf.UNSUPPORTED("""COMPUTED_VALUE"""),"Gilbert") -> Gilbert | C8: =IFERROR(__xludf.UNSUPPORTED("""COMPUTED_VALUE"""),"HXT") -> HXT | D8: =IFERROR(__xludf.UNSUPPORTED("""COMPUTED_VALUE"""),"Little Shop of Horrors") -> Little Shop of Horrors | E8: =IFERROR(__xludf.UNSUPPORTED("""COMPUTED_VALUE"""),45237) -> 45237 | F8: =IFERROR(__xludf.UNSUPPORTED("""COMPUTED_VALUE"""),45241) -> 45241 | G8: =IFERROR(__xludf.UNSUPPORTED("""COMPUTED_VALUE"""),"direct link") -> direct link | H8: =IFERROR(__xludf.UNSUPPORTED("""COMPUTED_VALUE"""),"Ciaran Mooney") -> Ciaran Mooney | I8: =IFERROR(__xludf.UNSUPPORTED("""COMPUTED_VALUE"""),"Erica Delaney") -> Erica Delaney | J8: =IFERROR(__xludf.UNSUPPORTED("""COMPUTED_VALUE"""),"Dermot O'Callaghan") -> Dermot O'Callaghan
A9: =IFERROR(__xludf.UNSUPPORTED("""COMPUTED_VALUE"""),"Northern") -> Northern | B9: =IFERROR(__xludf.UNSUPPORTED("""COMPUTED_VALUE"""),"Gilbert") -> Gilbert | C9: =IFERROR(__xludf.UNSUPPORTED("""COMPUTED_VALUE"""),"St. Patricks Choral Society") -> St. Patricks Choral Society | D9: =IFERROR(__xludf.UNSUPPORTED("""COMPUTED_VALUE"""),"All Shook Up") -> All Shook Up | E9: =IFERROR(__xludf.UNSUPPORTED("""COMPUTED_VALUE"""),45238) -> 45238 | F9: =IFERROR(__xludf.UNSUPPORTED("""COMPUTED_VALUE"""),45241) -> 45241 | G9: =IFERROR(__xludf.UNSUPPORTED("""COMPUTED_VALUE"""),"direct link") -> direct link | H9: =IFERROR(__xludf.UNSUPPORTED("""COMPUTED_VALUE"""),"Simon Pyper") -> Simon Pyper | I9: =IFERROR(__xludf.UNSUPPORTED("""COMPUTED_VALUE"""),"Alex McFarlane") -> Alex McFarlane | J9: =IFERROR(__xludf.UNSUPPORTED("""COMPUTED_VALUE"""),"Wilson Shields") -> Wilson Shields
A10: =IFERROR(__xludf.UNSUPPORTED("""COMPUTED_VALUE"""),"Eastern") -> Eastern | B10: =IFERROR(__xludf.UNSUPPORTED("""COMPUTED_VALUE"""),"Gilbert") -> Gilbert | C10: =IFERROR(__xludf.UNSUPPORTED("""COMPUTED_VALUE"""),"Coolmine") -> Coolmine | D10: =IFERROR(__xludf.UNSUPPORTED("""COMPUTED_VALUE"""),"Seussical! The Musical") -> Seussical! The Musical | E10: =IFERROR(__xludf.UNSUPPORTED("""COMPUTED_VALUE"""),45244) -> 45244 | F10: =IFERROR(__xludf.UNSUPPORTED("""COMPUTED_VALUE"""),45248) -> 45248 | G10: =IFERROR(__xludf.UNSUPPORTED("""COMPUTED_VALUE"""),"direct link") -> direct link | H10: =IFERROR(__xludf.UNSUPPORTED("""COMPUTED_VALUE"""),"Pat McElwain") -> Pat McElwain | I10: =IFERROR(__xludf.UNSUPPORTED("""COMPUTED_VALUE"""),"Nicole McDonald") -> Nicole McDonald | J10: =IFERROR(__xludf.UNSUPPORTED("""COMPUTED_VALUE"""),"Caitriona Ní Threasaigh") -> Caitriona Ní Threasaigh
A11: =IFERROR(__xludf.UNSUPPORTED("""COMPUTED_VALUE"""),"Northern") -> Northern | B11: =IFERROR(__xludf.UNSUPPORTED("""COMPUTED_VALUE"""),"Gilbert") -> Gilbert | C11: =IFERROR(__xludf.UNSUPPORTED("""COMPUTED_VALUE"""),"Newcastle Glees") -> Newcastle Glees | D11: =IFERROR(__xludf.UNSUPPORTED("""COMPUTED_VALUE"""),"Urinetown") -> Urinetown | E11: =IFERROR(__xludf.UNSUPPORTED("""COMPUTED_VALUE"""),45246) -> 45246 | F11: =IFERROR(__xludf.UNSUPPORTED("""COMPUTED_VALUE"""),45255) -> 45255 | G11: =IFERROR(__xludf.UNSUPPORTED("""COMPUTED_VALUE"""),"Live on Jan 24th") -> Live on Jan 24th | H11: =IFERROR(__xludf.UNSUPPORTED("""COMPUTED_VALUE"""),"Laura Kerr") -> Laura Kerr | I11: =IFERROR(__xludf.UNSUPPORTED("""COMPUTED_VALUE"""),"Clare Donnelly") -> Clare Donnelly | J11: =IFERROR(__xludf.UNSUPPORTED("""COMPUTED_VALUE"""),"Mark Tilley") -> Mark Tilley
A12: =IFERROR(__xludf.UNSUPPORTED("""COMPUTED_VALUE"""),"Midlands") -> Midlands | B12: =IFERROR(__xludf.UNSUPPORTED("""COMPUTED_VALUE"""),"Gilbert") -> Gilbert | C12: =IFERROR(__xludf.UNSUPPORTED("""COMPUTED_VALUE"""),"Portlaoise") -> Portlaoise | D12: =IFERROR(__xludf.UNSUPPORTED("""COMPUTED_VALUE"""),"Made in Dagenham") -> Made in Dagenham | E12: =IFERROR(__xludf.UNSUPPORTED("""COMPUTED_VALUE"""),45248) -> 45248 | F12: =IFERROR(__xludf.UNSUPPORTED("""COMPUTED_VALUE"""),45255) -> 45255 | G12: =IFERROR(__xludf.UNSUPPORTED("""COMPUTED_VALUE"""),"Live on Jan 26th") -> Live on Jan 26th | H12: =IFERROR(__xludf.UNSUPPORTED("""COMPUTED_VALUE"""),"Art McGauran") -> Art McGauran | I12: =IFERROR(__xludf.UNSUPPORTED("""COMPUTED_VALUE"""),"Stephanie Browne") -> Stephanie Browne | J12: =IFERROR(__xludf.UNSUPPORTED("""COMPUTED_VALUE"""),"Mary Rose McNally") -> Mary Rose McNally
A13: =IFERROR(__xludf.UNSUPPORTED("""COMPUTED_VALUE"""),"Eastern") -> Eastern | B13: =IFERROR(__xludf.UNSUPPORTED("""COMPUTED_VALUE"""),"Gilbert") -> Gilbert | C13: =IFERROR(__xludf.UNSUPPORTED("""COMPUTED_VALUE"""),"UCD") -> UCD | D13: =IFERROR(__xludf.UNSUPPORTED("""COMPUTED_VALUE"""),"Footloose") -> Footloose | E13: =IFERROR(__xludf.UNSUPPORTED("""COMPUTED_VALUE"""),45252) -> 45252 | F13: =IFERROR(__xludf.UNSUPPORTED("""COMPUTED_VALUE"""),45255) -> 45255 | G13: =IFERROR(__xludf.UNSUPPORTED("""COMPUTED_VALUE"""),"direct link") -> direct link | H13: =IFERROR(__xludf.UNSUPPORTED("""COMPUTED_VALUE"""),"Becca Lennon") -> Becca Lennon | I13: =IFERROR(__xludf.UNSUPPORTED("""COMPUTED_VALUE"""),"Maya Gaul") -> Maya Gaul | J13: =IFERROR(__xludf.UNSUPPORTED("""COMPUTED_VALUE"""),"Edie Weinstein") -> Edie Weinstein
A14: =IFERROR(__xludf.UNSUPPORTED("""COMPUTED_VALUE"""),"South-Western") -> South-Western | B14: =IFERROR(__xludf.UNSUPPORTED("""COMPUTED_VALUE"""),"Gilbert") -> Gilbert | C14: =IFERROR(__xludf.UNSUPPORTED("""COMPUTED_VALUE"""),"Cecilian MS Limerick") -> Cecilian MS Limerick | D14: =IFERROR(__xludf.UNSUPPORTED("""COMPUTED_VALUE"""),"Shrek") -> Shrek | E14: =IFERROR(__xludf.UNSUPPORTED("""COMPUTED_VALUE"""),45252) -> 45252 | F14: =IFERROR(__xludf.UNSUPPORTED("""COMPUTED_VALUE"""),45256) -> 45256 | G14: =IFERROR(__xludf.UNSUPPORTED("""COMPUTED_VALUE"""),"Live on Jan 29th") -> Live on Jan 29th | H14: =IFERROR(__xludf.UNSUPPORTED("""COMPUTED_VALUE"""),"Des Henn") -> Des Henn | I14: =IFERROR(__xludf.UNSUPPORTED("""COMPUTED_VALUE"""),"Barbara Meany") -> Barbara Meany | J14: =IFERROR(__xludf.UNSUPPORTED("""COMPUTED_VALUE"""),"Michael Young") -> Michael Young
A15: =IFERROR(__xludf.UNSUPPORTED("""COMPUTED_VALUE"""),"South-Eastern") -> South-Eastern | B15: =IFERROR(__xludf.UNSUPPORTED("""COMPUTED_VALUE"""),"Gilbert") -> Gilbert | C15: =IFERROR(__xludf.UNSUPPORTED("""COMPUTED_VALUE"""),"Carnew") -> Carnew | D15: =IFERROR(__xludf.UNSUPPORTED("""COMPUTED_VALUE"""),"The Addams Family") -> The Addams Family | E15: =IFERROR(__xludf.UNSUPPORTED("""COMPUTED_VALUE"""),45257) -> 45257 | F15: =IFERROR(__xludf.UNSUPPORTED("""COMPUTED_VALUE"""),45262) -> 45262 | G15: =IFERROR(__xludf.UNSUPPORTED("""COMPUTED_VALUE"""),"TBC") -> TBC | H15: =IFERROR(__xludf.UNSUPPORTED("""COMPUTED_VALUE"""),"Michael Dunbar") -> Michael Dunbar | I15: =IFERROR(__xludf.UNSUPPORTED("""COMPUTED_VALUE"""),"Graham Finnerty") -> Graham Finnerty | J15: =IFERROR(__xludf.UNSUPPORTED("""COMPUTED_VALUE"""),"Conor McCarthy") -> Conor McCarthy
A16: =IFERROR(__xludf.UNSUPPORTED("""COMPUTED_VALUE"""),"South-Eastern") -> South-Eastern | B16: =IFERROR(__xludf.UNSUPPORTED("""COMPUTED_VALUE"""),"Gilbert") -> Gilbert | C16: =IFERROR(__xludf.UNSUPPORTED("""COMPUTED_VALUE"""),"Oyster Lane Theatre Group") -> Oyster Lane Theatre Group | D16: =IFERROR(__xludf.UNSUPPORTED("""COMPUTED_VALUE"""),"The Producers") -> The Producers | E16: =IFERROR(__xludf.UNSUPPORTED("""COMPUTED_VALUE"""),45258) -> 45258 | F16: =IFERROR(__xludf.UNSUPPORTED("""COMPUTED_VALUE"""),45261) -> 45261 | G16: =IFERROR(__xludf.UNSUPPORTED("""COMPUTED_VALUE"""),"Live on Jan 31st") -> Live on Jan 31st | H16: =IFERROR(__xludf.UNSUPPORTED("""COMPUTED_VALUE"""),"Stephen Acton") -> Stephen Acton | I16: =IFERROR(__xludf.UNSUPPORTED("""COMPUTED_VALUE"""),"Jonny Smith") -> Jonny Smith | J16: =IFERROR(__xludf.UNSUPPORTED("""COMPUTED_VALUE"""),"Patrick Clancy") -> Patrick Clancy
A17: =IFERROR(__xludf.UNSUPPORTED("""COMPUTED_VALUE"""),"Western") -> Western | B17: =IFERROR(__xludf.UNSUPPORTED("""COMPUTED_VALUE"""),"Gilbert") -> Gilbert | C17: =IFERROR(__xludf.UNSUPPORTED("""COMPUTED_VALUE"""),"GUMS") -> GUMS | D17: =IFERROR(__xludf.UNSUPPORTED("""COMPUTED_VALUE"""),"American Idiot!") -> American Idiot! | E17: =IFERROR(__xludf.UNSUPPORTED("""COMPUTED_VALUE"""),45321) -> 45321 | F17: =IFERROR(__xludf.UNSUPPORTED("""COMPUTED_VALUE"""),45325) -> 45325 | H17: =IFERROR(__xludf.UNSUPPORTED("""COMPUTED_VALUE"""),"Aisling Fox") -> Aisling Fox | I17: =IFERROR(__xludf.UNSUPPORTED("""COMPUTED_VALUE"""),"Jodie Finn") -> Jodie Finn | J17: =IFERROR(__xludf.UNSUPPORTED("""COMPUTED_VALUE"""),"Robert Cosgrove") -> Robert Cosgrove
A18: =IFERROR(__xludf.UNSUPPORTED("""COMPUTED_VALUE"""),"Northern") -> Northern | B18: =IFERROR(__xludf.UNSUPPORTED("""COMPUTED_VALUE"""),"Gilbert") -> Gilbert | C18: =IFERROR(__xludf.UNSUPPORTED("""COMPUTED_VALUE"""),"Newcastle Glees Jr") -> Newcastle Glees Jr | D18: =IFERROR(__xludf.UNSUPPORTED("""COMPUTED_VALUE"""),"Beauty & The Beast") -> Beauty & The Beast | E18: =IFERROR(__xludf.UNSUPPORTED("""COMPUTED_VALUE"""),45331) -> 45331 | F18: =IFERROR(__xludf.UNSUPPORTED("""COMPUTED_VALUE"""),45339) -> 45339 | H18: =IFERROR(__xludf.UNSUPPORTED("""COMPUTED_VALUE"""),"Drian Mullan") -> Drian Mullan | I18: =IFERROR(__xludf.UNSUPPORTED("""COMPUTED_VALUE"""),"Gordon Donaldson") -> Gordon Donaldson | J18: =IFERROR(__xludf.UNSUPPORTED("""COMPUTED_VALUE"""),"Ria Maguire") -> Ria Maguire
A19: =IFERROR(__xludf.UNSUPPORTED("""COMPUTED_VALUE"""),"Midlands") -> Midlands | B19: =IFERROR(__xludf.UNSUPPORTED("""COMPUTED_VALUE"""),"Gilbert") -> Gilbert | C19: =IFERROR(__xludf.UNSUPPORTED("""COMPUTED_VALUE"""),"Tullamore") -> Tullamore | D19: =IFERROR(__xludf.UNSUPPORTED("""COMPUTED_VALUE"""),"Rock of Ages") -> Rock of Ages | E19: =IFERROR(__xludf.UNSUPPORTED("""COMPUTED_VALUE"""),45332) -> 45332 | F19: =IFERROR(__xludf.UNSUPPORTED("""COMPUTED_VALUE"""),45339) -> 45339 | H19: =IFERROR(__xludf.UNSUPPORTED("""COMPUTED_VALUE"""),"Claire Tighe") -> Claire Tighe | I19: =IFERROR(__xludf.UNSUPPORTED("""COMPUTED_VALUE"""),"Claire Tighe") -> Claire Tighe | J19: =IFERROR(__xludf.UNSUPPORTED("""COMPUTED_VALUE"""),"Enda O'Connor") -> Enda O'Connor
A20: =IFERROR(__xludf.UNSUPPORTED("""COMPUTED_VALUE"""),"Western") -> Western | B20: =IFERROR(__xludf.UNSUPPORTED("""COMPUTED_VALUE"""),"Gilbert") -> Gilbert | C20: =IFERROR(__xludf.UNSUPPORTED("""COMPUTED_VALUE"""),"Ballinrobe") -> Ballinrobe | D20: =IFERROR(__xludf.UNSUPPORTED("""COMPUTED_VALUE"""),"Phantom of the Opera") -> Phantom of the Opera | E20: =IFERROR(__xludf.UNSUPPORTED("""COMPUTED_VALUE"""),45333) -> 45333 | F20: =IFERROR(__xludf.UNSUPPORTED("""COMPUTED_VALUE"""),45340) -> 45340 | H20: =IFERROR(__xludf.UNSUPPORTED("""COMPUTED_VALUE"""),"Alan Greaney") -> Alan Greaney | I20: =IFERROR(__xludf.UNSUPPORTED("""COMPUTED_VALUE"""),"Aoife McClafferty") -> Aoife McClafferty | J20: =IFERROR(__xludf.UNSUPPORTED("""COMPUTED_VALUE"""),"Finola Higgins") -> Finola Higgins
A21: =IFERROR(__xludf.UNSUPPORTED("""COMPUTED_VALUE"""),"South-Western") -> South-Western | B21: =IFERROR(__xludf.UNSUPPORTED("""COMPUTED_VALUE"""),"Gilbert") -> Gilbert | C21: =IFERROR(__xludf.UNSUPPORTED("""COMPUTED_VALUE"""),"Shannon MS") -> Shannon MS | D21: =IFERROR(__xludf.UNSUPPORTED("""COMPUTED_VALUE"""),"The Little Mermaid") -> The Little Mermaid | E21: =IFERROR(__xludf.UNSUPPORTED("""COMPUTED_VALUE"""),45333) -> 45333 | F21: =IFERROR(__xludf.UNSUPPORTED("""COMPUTED_VALUE"""),45339) -> 45339 | H21: =IFERROR(__xludf.UNSUPPORTED("""COMPUTED_VALUE"""),"Tony Finnegan") -> Tony Finnegan | I21: =IFERROR(__xludf.UNSUPPORTED("""COMPUTED_VALUE"""),"Karen Barrett") -> Karen Barrett | J21: =IFERROR(__xludf.UNSUPPORTED("""COMPUTED_VALUE"""),"Shane Farrell") -> Shane Farrell
A22: =IFERROR(__xludf.UNSUPPORTED("""COMPUTED_VALUE"""),"Eastern") -> Eastern | B22: =IFERROR(__xludf.UNSUPPORTED("""COMPUTED_VALUE"""),"Gilbert") -> Gilbert | C22: =IFERROR(__xludf.UNSUPPORTED("""COMPUTED_VALUE"""),"Trim") -> Trim | D22: =IFERROR(__xludf.UNSUPPORTED("""COMPUTED_VALUE"""),"9 to 5 ") -> 9 to 5 | E22: =IFERROR(__xludf.UNSUPPORTED("""COMPUTED_VALUE"""),45334) -> 45334 | F22: =IFERROR(__xludf.UNSUPPORTED("""COMPUTED_VALUE"""),45339) -> 45339 | H22: =IFERROR(__xludf.UNSUPPORTED("""COMPUTED_VALUE"""),"Stephen Acton") -> Stephen Acton | I22: =IFERROR(__xludf.UNSUPPORTED("""COMPUTED_VALUE"""),"Laura Douglas") -> Laura Douglas | J22: =IFERROR(__xludf.UNSUPPORTED("""COMPUTED_VALUE"""),"Dermot O'Callaghan") -> Dermot O'Callaghan
A23: =IFERROR(__xludf.UNSUPPORTED("""COMPUTED_VALUE"""),"South-Western") -> South-Western | B23: =IFERROR(__xludf.UNSUPPORTED("""COMPUTED_VALUE"""),"Gilbert") -> Gilbert | C23: =IFERROR(__xludf.UNSUPPORTED("""COMPUTED_VALUE"""),"Tipperary") -> Tipperary | D23: =IFERROR(__xludf.UNSUPPORTED("""COMPUTED_VALUE"""),"Young Frankenstein") -> Young Frankenstein | E23: =IFERROR(__xludf.UNSUPPORTED("""COMPUTED_VALUE"""),45334) -> 45334 | F23: =IFERROR(__xludf.UNSUPPORTED("""COMPUTED_VALUE"""),45339) -> 45339 | H23: =IFERROR(__xludf.UNSUPPORTED("""COMPUTED_VALUE"""),"Paul Norton") -> Paul Norton | I23: =IFERROR(__xludf.UNSUPPORTED("""COMPUTED_VALUE"""),"Stephanie Browne") -> Stephanie Browne | J23: =IFERROR(__xludf.UNSUPPORTED("""COMPUTED_VALUE"""),"Mary Rose McNally") -> Mary Rose McNally
A24: =IFERROR(__xludf.UNSUPPORTED("""COMPUTED_VALUE"""),"Eastern") -> Eastern | B24: =IFERROR(__xludf.UNSUPPORTED("""COMPUTED_VALUE"""),"Gilbert") -> Gilbert | C24: =IFERROR(__xludf.UNSUPPORTED("""COMPUTED_VALUE"""),"Malahide") -> Malahide | D24: =IFERROR(__xludf.UNSUPPORTED("""COMPUTED_VALUE"""),"Cry Baby") -> Cry Baby | E24: =IFERROR(__xludf.UNSUPPORTED("""COMPUTED_VALUE"""),45335) -> 45335 | F24: =IFERROR(__xludf.UNSUPPORTED("""COMPUTED_VALUE"""),45339) -> 45339 | H24: =IFERROR(__xludf.UNSUPPORTED("""COMPUTED_VALUE"""),"EJ Reilly") -> EJ Reilly | I24: =IFERROR(__xludf.UNSUPPORTED("""COMPUTED_VALUE"""),"Jules McNamra") -> Jules McNamra | J24: =IFERROR(__xludf.UNSUPPORTED("""COMPUTED_VALUE"""),"Dave McGauran") -> Dave McGauran
A25: =IFERROR(__xludf.UNSUPPORTED("""COMPUTED_VALUE"""),"Eastern") -> Eastern | B25: =IFERROR(__xludf.UNSUPPORTED("""COMPUTED_VALUE"""),"Gilbert") -> Gilbert | C25: =IFERROR(__xludf.UNSUPPORTED("""COMPUTED_VALUE"""),"Entr'acte") -> Entr'acte | D25: =IFERROR(__xludf.UNSUPPORTED("""COMPUTED_VALUE"""),"Guys and Dolls") -> Guys and Dolls | E25: =IFERROR(__xludf.UNSUPPORTED("""COMPUTED_VALUE"""),45350) -> 45350 | F25: =IFERROR(__xludf.UNSUPPORTED("""COMPUTED_VALUE"""),45353) -> 45353 | H25: =IFERROR(__xludf.UNSUPPORTED("""COMPUTED_VALUE"""),"Niamh McGowan") -> Niamh McGowan | I25: =IFERROR(__xludf.UNSUPPORTED("""COMPUTED_VALUE"""),"Leah Meagher") -> Leah Meagher | J25: =IFERROR(__xludf.UNSUPPORTED("""COMPUTED_VALUE"""),"Roisin Heenan") -> Roisin Heenan
A26: =IFERROR(__xludf.UNSUPPORTED("""COMPUTED_VALUE"""),"Midlands") -> Midlands | B26: =IFERROR(__xludf.UNSUPPORTED("""COMPUTED_VALUE"""),"Gilbert") -> Gilbert | C26: =IFERROR(__xludf.UNSUPPORTED("""COMPUTED_VALUE"""),"Athlone MS") -> Athlone MS | D26: =IFERROR(__xludf.UNSUPPORTED("""COMPUTED_VALUE"""),"Urinetown") -> Urinetown | E26: =IFERROR(__xludf.UNSUPPORTED("""COMPUTED_VALUE"""),45352) -> 45352 | F26: =IFERROR(__xludf.UNSUPPORTED("""COMPUTED_VALUE"""),45360) -> 45360 | H26: =IFERROR(__xludf.UNSUPPORTED("""COMPUTED_VALUE"""),"Alfie Kilduff") -> Alfie Kilduff | I26: =IFERROR(__xludf.UNSUPPORTED("""COMPUTED_VALUE"""),"Chris Corroon") -> Chris Corroon | J26: =IFERROR(__xludf.UNSUPPORTED("""COMPUTED_VALUE"""),"Ger Madden") -> Ger Madden
A27: =IFERROR(__xludf.UNSUPPORTED("""COMPUTED_VALUE"""),"South-Eastern") -> South-Eastern | B27: =IFERROR(__xludf.UNSUPPORTED("""COMPUTED_VALUE"""),"Gilbert") -> Gilbert | C27: =IFERROR(__xludf.UNSUPPORTED("""COMPUTED_VALUE"""),"NRMS") -> NRMS | D27: =IFERROR(__xludf.UNSUPPORTED("""COMPUTED_VALUE"""),"Fiddler on the Roof") -> Fiddler on the Roof | E27: =IFERROR(__xludf.UNSUPPORTED("""COMPUTED_VALUE"""),45356) -> 45356 | F27: =IFERROR(__xludf.UNSUPPORTED("""COMPUTED_VALUE"""),45360) -> 45360 | H27: =IFERROR(__xludf.UNSUPPORTED("""COMPUTED_VALUE"""),"Derek Shannon") -> Derek Shannon | I27: =IFERROR(__xludf.UNSUPPORTED("""COMPUTED_VALUE"""),"Anne-Marie Cooney") -> Anne-Marie Cooney | J27: =IFERROR(__xludf.UNSUPPORTED("""COMPUTED_VALUE"""),"Jimmy Brockie") -> Jimmy Brockie
A28: =IFERROR(__xludf.UNSUPPORTED("""COMPUTED_VALUE"""),"Eastern") -> Eastern | B28: =IFERROR(__xludf.UNSUPPORTED("""COMPUTED_VALUE"""),"Gilbert") -> Gilbert | C28: =IFERROR(__xludf.UNSUPPORTED("""COMPUTED_VALUE"""),"UCD") -> UCD | D28: =IFERROR(__xludf.UNSUPPORTED("""COMPUTED_VALUE"""),"Gypsy") -> Gypsy | E28: =IFERROR(__xludf.UNSUPPORTED("""COMPUTED_VALUE"""),45357) -> 45357 | F28: =IFERROR(__xludf.UNSUPPORTED("""COMPUTED_VALUE"""),45360) -> 45360 | H28: =IFERROR(__xludf.UNSUPPORTED("""COMPUTED_VALUE"""),"Aoife Joy Keogh") -> Aoife Joy Keogh | I28: =IFERROR(__xludf.UNSUPPORTED("""COMPUTED_VALUE"""),"Megan O'Neill") -> Megan O'Neill | J28: =IFERROR(__xludf.UNSUPPORTED("""COMPUTED_VALUE"""),"Dermot Edmondson") -> Dermot Edmondson
A29: =IFERROR(__xludf.UNSUPPORTED("""COMPUTED_VALUE"""),"Eastern") -> Eastern | B29: =IFERROR(__xludf.UNSUPPORTED("""COMPUTED_VALUE"""),"Gilbert") -> Gilbert | C29: =IFERROR(__xludf.UNSUPPORTED("""COMPUTED_VALUE"""),"Teachers") -> Teachers | D29: =IFERROR(__xludf.UNSUPPORTED("""COMPUTED_VALUE"""),"Hunchback of Notre Dame") -> Hunchback of Notre Dame | E29: =IFERROR(__xludf.UNSUPPORTED("""COMPUTED_VALUE"""),45363) -> 45363 | F29: =IFERROR(__xludf.UNSUPPORTED("""COMPUTED_VALUE"""),45367) -> 45367 | H29: =IFERROR(__xludf.UNSUPPORTED("""COMPUTED_VALUE"""),"Ciarán Mooney") -> Ciarán Mooney | I29: =IFERROR(__xludf.UNSUPPORTED("""COMPUTED_VALUE"""),"Ciarán Mooney & Nicole McDonald") -> Ciarán Mooney & Nicole McDonald | J29: =IFERROR(__xludf.UNSUPPORTED("""COMPUTED_VALUE"""),"Dermot O'Callaghan") -> Dermot O'Callaghan
A30: =IFERROR(__xludf.UNSUPPORTED("""COMPUTED_VALUE"""),"Northern") -> Northern | B30: =IFERROR(__xludf.UNSUPPORTED("""COMPUTED_VALUE"""),"Gilbert") -> Gilbert | C30: =IFERROR(__xludf.UNSUPPORTED("""COMPUTED_VALUE"""),"Newcastle Glees") -> Newcastle Glees | D30: =IFERROR(__xludf.UNSUPPORTED("""COMPUTED_VALUE"""),"Calendar Girls") -> Calendar Girls | E30: =IFERROR(__xludf.UNSUPPORTED("""COMPUTED_VALUE"""),45365) -> 45365 | F30: =IFERROR(__xludf.UNSUPPORTED("""COMPUTED_VALUE"""),45374) -> 45374 | H30: =IFERROR(__xludf.UNSUPPORTED("""COMPUTED_VALUE"""),"Laura Kerr") -> Laura Kerr | I30: =IFERROR(__xludf.UNSUPPORTED("""COMPUTED_VALUE"""),"Clare Donnelly") -> Clare Donnelly | J30: =IFERROR(__xludf.UNSUPPORTED("""COMPUTED_VALUE"""),"Mary Tilley") -> Mary Tilley
A31: =IFERROR(__xludf.UNSUPPORTED("""COMPUTED_VALUE"""),"South-Western") -> South-Western | B31: =IFERROR(__xludf.UNSUPPORTED("""COMPUTED_VALUE"""),"Gilbert") -> Gilbert | C31: =IFERROR(__xludf.UNSUPPORTED("""COMPUTED_VALUE"""),"Thurles") -> Thurles | D31: =IFERROR(__xludf.UNSUPPORTED("""COMPUTED_VALUE"""),"Big Fish") -> Big Fish | E31: =IFERROR(__xludf.UNSUPPORTED("""COMPUTED_VALUE"""),45370) -> 45370 | F31: =IFERROR(__xludf.UNSUPPORTED("""COMPUTED_VALUE"""),45374) -> 45374 | H31: =IFERROR(__xludf.UNSUPPORTED("""COMPUTED_VALUE"""),"Oliver Hurley") -> Oliver Hurley | I31: =IFERROR(__xludf.UNSUPPORTED("""COMPUTED_VALUE"""),"Oliver Hurley") -> Oliver Hurley | J31: =IFERROR(__xludf.UNSUPPORTED("""COMPUTED_VALUE"""),"Mary Rose McNally") -> Mary Rose McNally
A32: =IFERROR(__xludf.UNSUPPORTED("""COMPUTED_VALUE"""),"South-Eastern") -> South-Eastern | B32: =IFERROR(__xludf.UNSUPPORTED("""COMPUTED_VALUE"""),"Gilbert") -> Gilbert | C32: =IFERROR(__xludf.UNSUPPORTED("""COMPUTED_VALUE"""),"DHMDS") -> DHMDS | D32: =IFERROR(__xludf.UNSUPPORTED("""COMPUTED_VALUE"""),"Beautiful : Carole King") -> Beautiful : Carole King | E32: =IFERROR(__xludf.UNSUPPORTED("""COMPUTED_VALUE"""),45376) -> 45376 | F32: =IFERROR(__xludf.UNSUPPORTED("""COMPUTED_VALUE"""),45381) -> 45381 | H32: =IFERROR(__xludf.UNSUPPORTED("""COMPUTED_VALUE"""),"David Hennessy") -> David Hennessy | I32: =IFERROR(__xludf.UNSUPPORTED("""COMPUTED_VALUE"""),"Michelle Condon") -> Michelle Condon | J32: =IFERROR(__xludf.UNSUPPORTED("""COMPUTED_VALUE"""),"Jimmy Brockie") -> Jimmy Brockie
A33: =IFERROR(__xludf.UNSUPPORTED("""COMPUTED_VALUE"""),"South-Western") -> South-Western | B33: =IFERROR(__xludf.UNSUPPORTED("""COMPUTED_VALUE"""),"Gilbert") -> Gilbert | C33: =IFERROR(__xludf.UNSUPPORTED("""COMPUTED_VALUE"""),"Ennis Musical Society") -> Ennis Musical Society | D33: =IFERROR(__xludf.UNSUPPORTED("""COMPUTED_VALUE"""),"The Wedding Singer") -> The Wedding Singer | E33: =IFERROR(__xludf.UNSUPPORTED("""COMPUTED_VALUE"""),45378) -> 45378 | F33: =IFERROR(__xludf.UNSUPPORTED("""COMPUTED_VALUE"""),45378) -> 45378 | H33: =IFERROR(__xludf.UNSUPPORTED("""COMPUTED_VALUE"""),"Jessica Bray") -> Jessica Bray | I33: =IFERROR(__xludf.UNSUPPORTED("""COMPUTED_VALUE"""),"Laura Kane Allis") -> Laura Kane Allis | J33: =IFERROR(__xludf.UNSUPPORTED("""COMPUTED_VALUE"""),"Shane Farrell") -> Shane Farrell
A34: =IFERROR(__xludf.UNSUPPORTED("""COMPUTED_VALUE"""),"Midlands") -> Midlands | B34: =IFERROR(__xludf.UNSUPPORTED("""COMPUTED_VALUE"""),"Gilbert") -> Gilbert | C34: =IFERROR(__xludf.UNSUPPORTED("""COMPUTED_VALUE"""),"Newbridge") -> Newbridge | D34: =IFERROR(__xludf.UNSUPPORTED("""COMPUTED_VALUE"""),"Legally Blonde") -> Legally Blonde | E34: =IFERROR(__xludf.UNSUPPORTED("""COMPUTED_VALUE"""),45383) -> 45383 | F34: =IFERROR(__xludf.UNSUPPORTED("""COMPUTED_VALUE"""),45388) -> 45388 | H34: =IFERROR(__xludf.UNSUPPORTED("""COMPUTED_VALUE"""),"Art McGauran") -> Art McGauran | I34: =IFERROR(__xludf.UNSUPPORTED("""COMPUTED_VALUE"""),"Aine Foley") -> Aine Foley | J34: =IFERROR(__xludf.UNSUPPORTED("""COMPUTED_VALUE"""),"Dave McGauran") -> Dave McGauran
